def sum_of_number() -> int:
    return 3


def myfunc() -> object:
    raise ValueError('exception 123 error')
